<?xml version="1.0"?>
<robot xmlns:xacro="http://www.ros.org/wiki/xacro">

    <xacro:macro name="wheel" params="name x y z roll pitch yaw">
        <joint name="${name}_joint" type="continuous">
            <parent link="base_link"/>
            <child link="${name}"/>
            <origin xyz="${x} ${y} ${z}" rpy="${roll} ${pitch} ${yaw}"/>
            <axis xyz="0 0 1"/>
        </joint>

        <link name="${name}">
            <visual>
                <geometry>
                    <cylinder radius="${wheel_radius}" length="${wheel_thickness}"/>
                </geometry>
                <material name="blue"/>
            </visual>
            <collision>
                <geometry>
                    <sphere radius="${wheel_radius}"/>
                </geometry>
            </collision>
            <xacro:inertial_cylinder mass="${wheel_mass}" length="${wheel_thickness}" radius="${wheel_radius}">
                <origin xyz="0 0 0" rpy="0 0 0"/>
            </xacro:inertial_cylinder>
        </link>

        <gazebo reference="${name}">
            <material>Gazebo/Blue</material>
            <mu1 value="1.0"/>
            <mu2 value="0.5"/>
        </gazebo>
    </xacro:macro>

</robot>
